Workbook

Sheet README
A1: 1BitVed - Game Data (balancing workbook)
A2: Generated 2026-09-28 from the Unity project. Read-only snapshot: editing cells here does NOT change the game.
A4: What this is | B4: Every balance-relevant number in the project - player, weapons, upgrades, enemies, spawners, boss, run/dungeon settings, economy - pulled from the serialized assets (prefabs, ScriptableObjects, scenes) and from hard-coded constants/formulas in the scripts.
A5: Where values come from | B5: Serialized values are read straight from the Unity YAML (so scene/prefab overrides are what you see, not script defaults). Hard-coded numbers and formulas were read from the C# and each row cites its source file.
A6: Colour key | B6: Navy = header. Light blue = section. Yellow = discrepancy / thing worth checking (details on the Findings sheet). Green = editable input for what-if formulas. Grey = derived by Excel formula.
A7: Formulas | B7: Derived columns (DPS, time-to-kill, projections, upgrade matrix) are live Excel formulas linked to the value cells, so you can change a source value and see the effect.
A8: Not verified in play | B8: Runtime interactions (spawner scaling order, boss shield windows, shop timer behaviour) come from reading code. Treat them as informed hypotheses and confirm in Play mode.
A9: Refresh | B9: This is a one-time extraction. If assets change, the workbook needs to be regenerated (the extraction script is not stored in the project).
A11: Sheets
A12: Player | B12: Health (coins), movement, dash, stomp, aggro, shooting rules, loadout
A13: Weapons | B13: AK47 / Shotgun / Pistol stats + derived DPS
A14: TTK Matrix | B14: Shots/seconds to kill every enemy, with editable damage inputs
A15: Upgrades | B15: All 12 cigs by effect field, tiers, rarity scaling, shop/pack rules
A16: Upgrade Matrix | B16: Effective values by tier x rarity
A17: Enemies | B17: Comparison table + melee/ranged/eye/pentagram details
A18: Spawner | B18: Roster, budget, runtime modifiers, per-level projection
A19: Boss | B19: MiniBoss1 parameters and derived attack pattern
A20: Run & Dungeon | B20: Rooms to boss, timer, generator presets, relics, achievements
A21: Economy | B21: Coin sources/sinks and derived expectations
A22: Findings | B22: Discrepancies and things that affect balance
A23: Raw Data | B23: Every remaining serialized field in long format (filterable)

Sheet Player
A1: Player, combat & economy-facing stats
A2: Player prefab: Assets/Prefabs/Temp -Player.prefab (used by RoguelikeMode and BossArena). Scene starting values from CoinManager.
A4: Category | B4: Parameter | C4: Value | D4: Unit | E4: Source | F4: Notes
A5: Health | B5: Health model | C5: Coins ARE health | E5: PlayerHealth.cs | F5: useCoinsAsHealth=1. Coin balance is HP; running out of coins on a hit = death.
A6: Health | B6: coinsLostPerHit | C6: 30 | D6: coins | E6: Assets/Prefabs/Temp -Player.prefab > PlayerHealth | F6: Flat cost of ANY damage source (melee, bullet, pentagram, boss). Script default is 100; prefab overrides to 30.
A7: Health | B7: damageCooldown (i-frames after a hit) | C7: 1 | D7: s | E7: Assets/Prefabs/Temp -Player.prefab > PlayerHealth
A8: Health | B8: knockbackForce | C8: 8 | D8: impulse | E8: Assets/Prefabs/Temp -Player.prefab > PlayerHealth
A9: Health | B9: knockbackDuration | C9: 0.8 | D9: s | E9: Assets/Prefabs/Temp -Player.prefab > PlayerHealth | F9: Field exists but is not read by ApplyKnockback (unused).
A10: Health | B10: deathDelay (before death UI) | C10: 3 | D10: s | E10: Assets/Prefabs/Temp -Player.prefab > PlayerHealth
A11: Health | B11: coinsToSpawnOnDamage | C11: 15 | D11: count | E11: Assets/Prefabs/Temp -Player.prefab > PlayerHealth | F11: Visual-only coins (coin script disabled, destroyed after coinLifetime). Not recoverable by the player.
A12: Health | B12: invincible (debug) | C12: 0 | D12: bool | E12: Assets/Prefabs/Temp -Player.prefab > PlayerHealth
A13: Health | B13: invincibility toggle key / works in build | C13: KeyCode 105 (= I) / enableToggleInBuild=1 | E13: Assets/Prefabs/Temp -Player.prefab > PlayerHealth | F13: Pressing I toggles god mode in shipping builds too.
A14: Coins | B14: startingCoins | C14: 50 | D14: coins | E14: Assets/Scenes/RoguelikeMode.unity > CoinManager | F14: Scene value (script default 0). BossArena identical.
A15: Coins | B15: startingMaxCoins (coin cap) | C15: 200 | D15: coins | E15: Assets/Scenes/RoguelikeMode.unity > CoinManager | F15: Pickups beyond the cap are discarded (AddCoins clamps).
A16: Coins | B16: Coin value per pickup | C16: 1 | D16: coins | E16: Assets/Prefabs/Coin.prefab
A17: Coins | B17: Hits to die from starting coins (derived) | C17: =ROUNDUP(C14/C6,0) | D17: hits | E17: formula | F17: Uses ROUNDUP: the final hit only needs to take you to 0.
A18: Coins | B18: Hits to die from a full purse (derived) | C18: =ROUNDUP(C15/C6,0) | D18: hits | E18: formula
A19: Coins | B19: magnetRange | C19: 2.6 | D19: u | E19: Assets/Prefabs/Temp -Player.prefab > PlayerCoinCollector
A20: Coins | B20: magnetStrength | C20: 30 | D20: u/s | E20: Assets/Prefabs/Temp -Player.prefab > PlayerCoinCollector
A21: Coins | B21: collectDistance | C21: 0.6 | D21: u | E21: Assets/Prefabs/Temp -Player.prefab > PlayerCoinCollector
A22: Movement | B22: baseMoveSpeed | C22: 4 | D22: u/s | E22: Assets/Prefabs/Temp -Player.prefab > PlayerController | F22: No speed upgrades exist in the current catalog.
A23: Dash | B23: dashSpeed | C23: 20 | D23: u/s | E23: Assets/Prefabs/Temp -Player.prefab > PlayerController
A24: Dash | B24: dashDuration | C24: 0.2 | D24: s | E24: Assets/Prefabs/Temp -Player.prefab > PlayerController
A25: Dash | B25: Dash distance (derived) | C25: =C23*C24 | D25: u | E25: formula | F25: Shortened by walls; dash aborts if <1 u of room (hard-coded).
A26: Dash | B26: dashCooldown | C26: 3 | D26: s | E26: Assets/Prefabs/Temp -Player.prefab > PlayerController | F26: Base charges = 1. Chain Dash adds charges AND adds to this cooldown; whole pool refills at once after the cooldown since last use.
A27: Dash | B27: invulnerableDuringDash | C27: 1 | D27: bool | E27: Assets/Prefabs/Temp -Player.prefab > PlayerController | F27: Also lets player pass through enemy colliders during the dash.
A28: Dash | B28: dashPassthroughRadius | C28: 1 | D28: u | E28: Assets/Prefabs/Temp -Player.prefab > PlayerController
A29: Dash | B29: dashEndClearRadius | C29: 1 | D29: u | E29: Assets/Prefabs/Temp -Player.prefab > PlayerController | F29: 0-damage push at dash end (always on).
A30: Dash | B30: deflectDetectionRadius | C30: 1.2 | D30: u | E30: Assets/Prefabs/Temp -Player.prefab > PlayerController | F30: Only with Dash Deflect cig.
A31: Dash | B31: Dash AoE hit rate | C31: every physics step; damage once/enemy/dash | E31: PlayerController.TickDashAoe | F31: Radius/damage/knockback come from Dash AoE cig.
A32: Dash | B32: Bulldozer pushRadius / pushStr | C32: 0.25 / 5 | D32: u / force | E32: Assets/Prefabs/Temp -Player.prefab > PlayerController
A33: Stomp | B33: stompDamage (base) | C33: 50 | D33: damage | E33: Assets/Prefabs/Temp -Player.prefab > PlayerStompController | F33: Plus cig bonuses (flat).
A34: Stomp | B34: stompRadius (base) | C34: 2.5 | D34: u | E34: Assets/Prefabs/Temp -Player.prefab > PlayerStompController | F34: Plus cig radius bonus.
A35: Stomp | B35: stompCooldown | C35: 2 | D35: s | E35: Assets/Prefabs/Temp -Player.prefab > PlayerStompController | F35: Base charges = 1. Chain Stomp adds charges and cooldown.
A36: Stomp | B36: stompPushBeyondRadius | C36: 0.5 | D36: u | E36: Assets/Prefabs/Temp -Player.prefab > PlayerStompController
A37: Stomp | B37: stompCostCoins (enabled?) | C37: 0 | D37: bool | E37: Assets/Prefabs/Temp -Player.prefab > PlayerStompController | F37: Off. If turned on, each stomp costs stompCoinCost coins (which is also HP).
A38: Stomp | B38: stompCoinCost | C38: 10 | D38: coins | E38: Assets/Prefabs/Temp -Player.prefab > PlayerStompController | F38: Inactive while stompCostCoins = 0.
A39: Stomp | B39: stompBulletSpeed / Lifetime (Stomp Circle cig) | C39: 12 / 2 | D39: u/s / s | E39: Assets/Prefabs/Temp -Player.prefab > PlayerStompController
A40: Stomp | B40: Stomp also destroys enemy bullets in radius | C40: yes | E40: PlayerStompController.DestroyBulletsInRange
A41: Aggro | B41: Enemy activation radius | C41: 10 | D41: u | E41: Assets/Prefabs/Temp -Player.prefab > ActivateEnemies
...

Sheet Weapons
A1: Weapons
A2: Source: Assets/Scripts/Weapons/*.asset (WeaponData ScriptableObjects). Grey columns are Excel formulas.
A4: Weapon | B4: Asset | C4: Type | D4: In player loadout? | E4: fireRate (shots/s) | F4: baseDamagePerShot | G4: Pellets per shot | H4: Magazine | I4: reloadTime (s) | J4: coneAngle (deg) | K4: coneRange (u) | L4: baseWidthMult | M4: topWidthMult | N4: baseDistanceRatio | O4: shapeProfile | P4: expansionCurve | Q4: maxPierceCount | R4: recoilStrength | S4: playerKnockback | T4: infinite reserve | U4: Time to empty mag (s) | V4: Damage per target per shot | W4: Max targets per shot | X4: Sustained DPS vs 1 target (incl. reload) | Y4: Burst DPS vs 1 target | Z4: Half-angle at base (deg) | AA4: Half-angle at max range (deg) | AB4: Notes
A5: AK47 | B5: Assets/Scripts/Weapons/MachineGun.asset | C5: Standard | D5: YES (primary, equipped at start) | E5: 10 | F5: 25 | G5: 1 | H5: 60 | I5: 0.8 | J5: 25 | K5: 30 | L5: 1 | M5: 0.45 | N5: 0.08 | O5: Linear | P5: 1 | Q5: 3 | R5: 0 | S5: 0 | T5: 1 | U5: =H5/E5 | V5: =F5 | W5: 1 | X5: =H5*F5/(H5/E5+I5) | Y5: =E5*F5 | Z5: =J5*L5 | AA5: =J5*M5 | AB5: Standard: damages ONLY the closest target in cone, 1 ammo per shot.
A6: Shotgun | B6: Assets/Scripts/Weapons/Shotgun.asset | C6: Shotgun | D6: YES (secondary) | E6: 3 | F6: 150 | G6: =Player!$C$44 | H6: 2 | I6: 1 | J6: 20 | K6: 30 | L6: 1 | M6: 0.535 | N6: 0.08 | O6: Linear | P6: 1 | Q6: 3 | R6: 1 | S6: 10 | T6: 1 | U6: =H6/E6 | V6: =F6 | W6: =G6 | X6: =H6*F6/(H6/E6+I6) | Y6: =E6*F6 | Z6: =J6*L6 | AA6: =J6*M6 | AB6: Each pellet hits a different target; one enemy takes at most ONE pellet per shot. 1 ammo per blast. Bonus pellets only add extra targets.
A7: Pistol | B7: Assets/Scripts/Weapons/Pistol.asset | C7: Piercer | D7: NO (asset exists, not in WeaponInventory) | E7: 2 | F7: 100 | G7: 1 | H7: 12 | I7: 0.5 | J7: 15 | K7: 30 | L7: 1 | M7: 0.7 | N7: 0.08 | O7: Linear | P7: 1 | Q7: 10 | R7: 0 | S7: 0 | T7: 1 | U7: =H7/E7 | V7: =F7 | W7: =Q7 | X7: =H7*F7/(H7/E7+I7) | Y7: =E7*F7 | Z7: =J7*L7 | AA7: =J7*M7 | AB7: Piercer: damage hits up to maxPierceCount targets in a line.
A9: How weapon numbers are used (from code)
A10: Every weapon is hitscan: damage is applied instantly when the shot fires; bullet visuals are cosmetic (bulletSpeed=100 on the shooter).
A11: Targets must be inside a trapezoid cone: half-angle goes from coneAngle*baseWidthMult (at coneRange*baseDistanceRatio) to coneAngle*topWidthMult (at coneRange), shaped by shapeProfile. With the current assets topWidthMult < baseWidthMult, so cones TAPER with distance.
A12: Fire interval = 1/fireRate, but shooting runs in FixedUpdate (0.02 s), so very high fire rates quantize to physics ticks.
A13: Auto-reload when the magazine is empty; R reloads manually. reloadTime is the full refill time. Ammo reserve is infinite for all weapons.
A14: Piercer (Pistol) applies damage to every enemy in its line up to maxPierceCount; Standard ignores maxPierceCount; Shotgun ignores it too.
A15: Upgrade hooks: slot bonus damage (+flat, Regular brand), crit chance/multiplier (Mild), fire-rate % (Electric), bonus pellets (Electric, shotgun only), bounce chains (Regular).
A16: Bounce chain: after the first hit, jumps to nearest un-hit enemy within coneRange of the current hop AND within 15 u of the first hit; each hop deals full damage and rolls its own crit.

Sheet TTK Matrix
A1: Time-to-kill matrix (editable inputs in green)
A2: Shots and seconds a single weapon needs to kill each enemy, from Weapons + Enemies sheets. Ignores crits, misses and reloads unless stated.
A4: Flat bonus damage (Regular-brand cig, slot bonus) | C4: 0
A5: Damage multiplier (Dash post-damage window, 1 = none) | C5: 1
A6: Fire-rate bonus (Electric cig, 0.45 = +45%) | C6: 0
A8: Shots to kill (ROUNDUP(HP / damage))
A9: Weapon | B9: Effective dmg / shot | C9: Enemy 1 | D9: Enemy 2 | E9: Enemy 3 | F9: Ranged | G9: Cthulhu Eye | H9: Boss shield | I9: Boss HP | J9: Spawner (300 HP)
A10: AK47 | B10: =ROUND((Weapons!F5+$C$4)*$C$5,0) | C10: =ROUNDUP(Enemies!$E$5/$B10,0) | D10: =ROUNDUP(Enemies!$E$6/$B10,0) | E10: =ROUNDUP(Enemies!$E$7/$B10,0) | F10: =ROUNDUP(Enemies!$E$9/$B10,0) | G10: =ROUNDUP(Enemies!$E$10/$B10,0) | H10: =ROUNDUP(1000/$B10,0) | I10: =ROUNDUP(Enemies!$E$11/$B10,0) | J10: =ROUNDUP(300/$B10,0)
A11: Shotgun | B11: =ROUND((Weapons!F6+$C$4)*$C$5,0) | C11: =ROUNDUP(Enemies!$E$5/$B11,0) | D11: =ROUNDUP(Enemies!$E$6/$B11,0) | E11: =ROUNDUP(Enemies!$E$7/$B11,0) | F11: =ROUNDUP(Enemies!$E$9/$B11,0) | G11: =ROUNDUP(Enemies!$E$10/$B11,0) | H11: =ROUNDUP(1000/$B11,0) | I11: =ROUNDUP(Enemies!$E$11/$B11,0) | J11: =ROUNDUP(300/$B11,0)
A12: Pistol | B12: =ROUND((Weapons!F7+$C$4)*$C$5,0) | C12: =ROUNDUP(Enemies!$E$5/$B12,0) | D12: =ROUNDUP(Enemies!$E$6/$B12,0) | E12: =ROUNDUP(Enemies!$E$7/$B12,0) | F12: =ROUNDUP(Enemies!$E$9/$B12,0) | G12: =ROUNDUP(Enemies!$E$10/$B12,0) | H12: =ROUNDUP(1000/$B12,0) | I12: =ROUNDUP(Enemies!$E$11/$B12,0) | J12: =ROUNDUP(300/$B12,0)
A14: Seconds to kill (first shot instant; excludes reloads)
A15: Weapon | B15: Effective dmg / shot | C15: Enemy 1 | D15: Enemy 2 | E15: Enemy 3 | F15: Ranged | G15: Cthulhu Eye | H15: Boss shield | I15: Boss HP | J15: Spawner (300 HP)
A16: AK47 | B16: =B10 | C16: =(C10-1)/(Weapons!E5*(1+$C$6)) | D16: =(D10-1)/(Weapons!E5*(1+$C$6)) | E16: =(E10-1)/(Weapons!E5*(1+$C$6)) | F16: =(F10-1)/(Weapons!E5*(1+$C$6)) | G16: =(G10-1)/(Weapons!E5*(1+$C$6)) | H16: =(H10-1)/(Weapons!E5*(1+$C$6)) | I16: =(I10-1)/(Weapons!E5*(1+$C$6)) | J16: =(J10-1)/(Weapons!E5*(1+$C$6))
A17: Shotgun | B17: =B11 | C17: =(C11-1)/(Weapons!E6*(1+$C$6)) | D17: =(D11-1)/(Weapons!E6*(1+$C$6)) | E17: =(E11-1)/(Weapons!E6*(1+$C$6)) | F17: =(F11-1)/(Weapons!E6*(1+$C$6)) | G17: =(G11-1)/(Weapons!E6*(1+$C$6)) | H17: =(H11-1)/(Weapons!E6*(1+$C$6)) | I17: =(I11-1)/(Weapons!E6*(1+$C$6)) | J17: =(J11-1)/(Weapons!E6*(1+$C$6))
A18: Pistol | B18: =B12 | C18: =(C12-1)/(Weapons!E7*(1+$C$6)) | D18: =(D12-1)/(Weapons!E7*(1+$C$6)) | E18: =(E12-1)/(Weapons!E7*(1+$C$6)) | F18: =(F12-1)/(Weapons!E7*(1+$C$6)) | G18: =(G12-1)/(Weapons!E7*(1+$C$6)) | H18: =(H12-1)/(Weapons!E7*(1+$C$6)) | I18: =(I12-1)/(Weapons!E7*(1+$C$6)) | J18: =(J12-1)/(Weapons!E7*(1+$C$6))
A20: Magazines needed to kill (ROUNDUP(shots / magazine))
A21: Weapon | B21: Effective dmg / shot | C21: Enemy 1 | D21: Enemy 2 | E21: Enemy 3 | F21: Ranged | G21: Cthulhu Eye | H21: Boss shield | I21: Boss HP | J21: Spawner (300 HP)
A22: AK47 | B22: =Weapons!H5 | C22: =ROUNDUP(C10/Weapons!$H5,0) | D22: =ROUNDUP(D10/Weapons!$H5,0) | E22: =ROUNDUP(E10/Weapons!$H5,0) | F22: =ROUNDUP(F10/Weapons!$H5,0) | G22: =ROUNDUP(G10/Weapons!$H5,0) | H22: =ROUNDUP(H10/Weapons!$H5,0) | I22: =ROUNDUP(I10/Weapons!$H5,0) | J22: =ROUNDUP(J10/Weapons!$H5,0)
A23: Shotgun | B23: =Weapons!H6 | C23: =ROUNDUP(C11/Weapons!$H6,0) | D23: =ROUNDUP(D11/Weapons!$H6,0) | E23: =ROUNDUP(E11/Weapons!$H6,0) | F23: =ROUNDUP(F11/Weapons!$H6,0) | G23: =ROUNDUP(G11/Weapons!$H6,0) | H23: =ROUNDUP(H11/Weapons!$H6,0) | I23: =ROUNDUP(I11/Weapons!$H6,0) | J23: =ROUNDUP(J11/Weapons!$H6,0)
A24: Pistol | B24: =Weapons!H7 | C24: =ROUNDUP(C12/Weapons!$H7,0) | D24: =ROUNDUP(D12/Weapons!$H7,0) | E24: =ROUNDUP(E12/Weapons!$H7,0) | F24: =ROUNDUP(F12/Weapons!$H7,0) | G24: =ROUNDUP(G12/Weapons!$H7,0) | H24: =ROUNDUP(H12/Weapons!$H7,0) | I24: =ROUNDUP(I12/Weapons!$H7,0) | J24: =ROUNDUP(J12/Weapons!$H7,0)
A26: Note: Boss HP is only damageable while its shield is down; the shield (1000) regenerates to full every time the boss leaves a wall. See Boss sheet.

Sheet Upgrades
A1: Upgrades ("cigs") - one row per effect field
A2: Source: Assets/Prefabs/Upgrades/**/*.asset (12 assets, all listed in __Pack Manager__ > CigPool). UpgradeCatalogSnapshot.md is out of date (13 old assets).
A4: Asset file | B4: Class | C4: ID | D4: Display name | E4: Brand | F4: Slot | G4: Has rarity roll? | H4: Shop cost (coins) | I4: Effect | J4: Tier 1 | K4: Tier 2 | L4: Tier 3 | M4: Tier 4 | N4: Scalar / flag | O4: Rarity scaling | P4: Feeds PackStats field | Q4: Notes
A5: Chain Dash.asset | B5: ChainDashCigData | C5: Electric-4 | D5: Chain Dash | E5: Electric | F5: Dash | G5: no | H5: 10 | I5: Extra dash charges | J5: 1 | K5: 2 | L5: 3 | M5: 4 | O5: no | P5: DashExtraCharges
A6: Chain Dash.asset | B6: ChainDashCigData | C6: Electric-4 | D6: Chain Dash | E6: Electric | F6: Dash | G6: no | H6: 10 | I6: Dash cooldown added (s) | J6: 0.25 | K6: 0.5 | L6: 0.75 | M6: 1 | O6: no | P6: DashCooldownPenalty
A7: Chain Stomp.asset | B7: ChainStompCigData | C7: Electric-3 | D7: Chain Stomp | E7: Electric | F7: Stomp | G7: no | H7: 10 | I7: Extra stomp charges | J7: 1 | K7: 2 | L7: 3 | M7: 4 | O7: no | P7: StompExtraCharges
A8: Chain Stomp.asset | B8: ChainStompCigData | C8: Electric-3 | D8: Chain Stomp | E8: Electric | F8: Stomp | G8: no | H8: 10 | I8: Stomp cooldown added (s) | J8: 0.5 | K8: 1 | L8: 1.5 | M8: 2 | O8: no | P8: StompCooldownPenalty
A9: Primary FireRate.asset | B9: FireRateCigData | C9: Electric-1 | D9: Primary Firerate | E9: Electric | F9: PrimaryWeapon | G9: no | H9: 10 | I9: Fire rate bonus (+%) | J9: 0.1 | K9: 0.2 | L9: 0.3 | M9: 0.45 | O9: no | P9: Primary/SecondaryFireRateBonus
A10: Secondary Pellet inc.asset | B10: ShotgunPelletCountCigData | C10: Electric-2 | D10: Inc Secondary Pellets | E10: Electric | F10: SecondaryWeapon | G10: no | H10: 0 | I10: Extra shotgun pellets | J10: 1 | K10: 2 | L10: 3 | M10: 4 | O10: no | P10: ShotgunBonusPellets | Q10: Buy cost is 0 (all others 10) - check if intentional.
A11: Dash Post Dmg.asset | B11: DashPostDamageCigData | C11: Mild-4 | D11: Dash PostDmg | E11: Mild | F11: Dash | G11: no | H11: 10 | I11: Post-dash damage multiplier (add) | J11: 0.25 | K11: 0.5 | L11: 0.75 | M11: 1 | O11: no | P11: DashDamageWindowMultiplier = 1 + bonus
A12: Dash Post Dmg.asset | B12: DashPostDamageCigData | C12: Mild-4 | D12: Dash PostDmg | E12: Mild | F12: Dash | G12: no | H12: 10 | I12: Post-dash window (s), not tiered | N12: 2 | O12: no | P12: DashDamageWindowDuration
A13: Primary Dmg & Crit.asset | B13: CritChanceCigData | C13: Mild-1 | D13: Primary Up | E13: Mild | F13: PrimaryWeapon | G13: YES | H13: 10 | I13: Crit chance (add, %) | J13: 0.1 | K13: 0.2 | L13: 0.3 | M13: 0.45 | O13: no | P13: Primary/SecondaryCritChance
A14: Primary Dmg & Crit.asset | B14: CritChanceCigData | C14: Mild-1 | D14: Primary Up | E14: Mild | F14: PrimaryWeapon | G14: YES | H14: 10 | I14: Crit damage multiplier (base) | N14: 1.5 | O14: YES: extra multiplier (x-1) is scaled by (1+rarity). Chance is NOT scaled. | P14: Primary/SecondaryCritMultiplier += (x-1)*(1+rarity)
A15: Secondary Dmg & Crit.asset | B15: CritChanceCigData | C15: Mild-2 | D15: Secondary Up | E15: Mild | F15: SecondaryWeapon | G15: YES | H15: 10 | I15: Crit chance (add, %) | J15: 0.1 | K15: 0.2 | L15: 0.3 | M15: 0.45 | O15: no | P15: Primary/SecondaryCritChance
A16: Secondary Dmg & Crit.asset | B16: CritChanceCigData | C16: Mild-2 | D16: Secondary Up | E16: Mild | F16: SecondaryWeapon | G16: YES | H16: 10 | I16: Crit damage multiplier (base) | N16: 1.5 | O16: YES: extra multiplier (x-1) is scaled by (1+rarity). Chance is NOT scaled. | P16: Primary/SecondaryCritMultiplier += (x-1)*(1+rarity)
A17: Stomp Power.asset | B17: StompPowerCigData | C17: Mild-3 | D17: Stomp Power | E17: Mild | F17: Stomp | G17: YES | H17: 10 | I17: Stomp flat damage bonus | J17: 2 | K17: 5 | L17: 9 | M17: 14 | O17: YES: round(dmg*(1+rarity)) | P17: StompBonusDamage
A18: Stomp Power.asset | B18: StompPowerCigData | C18: Mild-3 | D18: Stomp Power | E18: Mild | F18: Stomp | G18: YES | H18: 10 | I18: Stomp radius bonus (u) | J18: 1 | K18: 2 | L18: 3 | M18: 4 | O18: no | P18: StompBonusRadius
A19: Dash AOEDmg.asset | B19: DashAoECigData | C19: Regular-4 | D19: Dash AOE Dmg | E19: Regular | F19: Dash | G19: YES | H19: 10 | I19: Dash AoE damage (once/enemy/dash) | J19: 8 | K19: 14 | L19: 20 | M19: 28 | O19: YES: round(dmg*(1+rarity)) | P19: DashAoeDamage
A20: Dash AOEDmg.asset | B20: DashAoECigData | C20: Regular-4 | D20: Dash AOE Dmg | E20: Regular | F20: Dash | G20: YES | H20: 10 | I20: Dash AoE knockback | J20: 12 | K20: 16 | L20: 20 | M20: 25 | O20: YES: knockback*(1+rarity) | P20: DashAoeKnockback
A21: Dash AOEDmg.asset | B21: DashAoECigData | C21: Regular-4 | D21: Dash AOE Dmg | E21: Regular | F21: Dash | G21: YES | H21: 10 | I21: Dash AoE radius (u), not tiered | N21: 2 | O21: no | P21: DashAoeRadius
A22: Primary DmgInc & Bullet Bounce.asset | B22: BulletBounceCigData | C22: Regular-1 | D22: Primary Bullet Bounce | E22: Regular | F22: PrimaryWeapon | G22: YES | H22: 10 | I22: Flat weapon damage bonus | J22: 5 | K22: 10 | L22: 15 | M22: 20 | O22: YES: round(dmg*(1+rarity)) | P22: Primary/SecondaryWeaponBonusDamage
A23: Primary DmgInc & Bullet Bounce.asset | B23: BulletBounceCigData | C23: Regular-1 | D23: Primary Bullet Bounce | E23: Regular | F23: PrimaryWeapon | G23: YES | H23: 10 | I23: Bullet bounce count | J23: 1 | K23: 2 | L23: 3 | M23: 4 | O23: no | P23: Primary/SecondaryBounceCount
A24: Secondary DmgInc & Bullet Bounce.asset | B24: BulletBounceCigData | C24: Regular-2 | D24: Secondary Bullet Bounce | E24: Regular | F24: SecondaryWeapon | G24: YES | H24: 10 | I24: Flat weapon damage bonus | J24: 5 | K24: 10 | L24: 15 | M24: 20 | O24: YES: round(dmg*(1+rarity)) | P24: Primary/SecondaryWeaponBonusDamage
A25: Secondary DmgInc & Bullet Bounce.asset | B25: BulletBounceCigData | C25: Regular-2 | D25: Secondary Bullet Bounce | E25: Regular | F25: SecondaryWeapon | G25: YES | H25: 10 | I25: Bullet bounce count | J25: 1 | K25: 2 | L25: 3 | M25: 4 | O25: no | P25: Primary/SecondaryBounceCount
A26: Stomp Circle.asset | B26: StompCircleCigData | C26: Regular-3 | D26: Stomp Circle | E26: Regular | F26: Stomp | G26: YES | H26: 10 | I26: Stomp flat damage bonus | J26: 2 | K26: 5 | L26: 9 | M26: 14 | O26: YES: round(dmg*(1+rarity)) | P26: StompBonusDamage
A27: Stomp Circle.asset | B27: StompCircleCigData | C27: Regular-3 | D27: Stomp Circle | E27: Regular | F27: Stomp | G27: YES | H27: 10 | I27: Stomp ring bullet count | J27: 4 | K27: 6 | L27: 8 | M27: 10 | O27: no | P27: StompBulletCount (each bullet = full stomp damage)
A29: Shop & pack rules (code)
A30: Pack capacity | B30: 5 cigs (Pack.MaxSlots). Buying a lineage you already hold replaces it in place.
A31: Offers | B31: ShopUIController.offerCount = 3 cards shown; CigPool.RollOffers() rolls every not-yet-bought lineage fresh, shuffled.
A32: Tier roll | B32: Uniform 1-4 (25% each) per offer, rerolled on every offer generation.
A33: Rarity roll | B33: Uniform over Common/Uncommon/Rare/Epic (25% each) but only if hasRarity; else Common.
A34: Rarity bonus | B34: Rarity Config: Common 0, Uncommon 0.10, Rare 0.25, Epic 0.50 (Assets/Prefabs/Upgrades/Rarity Config.asset).
A35: Bought lineage | B35: Removed from the pool permanently for the run (never re-offered, even after burning).
A36: Brand exclusivity | B36: Mild and Regular cigs targeting the SAME slot are mutually exclusive (buying one prompts replacing the other). Electric is unrestricted.
A37: Burning | B37: A held cig can be burned: acts as Tier 4 (rarity unchanged) for the NEXT level only, then is removed at the level boundary.
A38: Reshuffle cost | B38: reshuffleBaseCost=5, +50% compounding per reshuffle this visit (cost = round(5 * 1.5^n)); resets every shop visit.
A39: Shop opens | B39: After each cleared dungeon except the last (before the boss). See Run & Dungeon.
A40: Debug grant in scene | B40: RoguelikeMode's __Pack Manager__ instance carries DebugUpgradeInjector entries: Chain Dash, Primary Dmg & Crit, Stomp Circle (Tier 1, Common) granted at Start, bypassing the shop. Verify before balancing runs.
A42: Reshuffle # | B42: Cost (coins)
A43: 0 | B43: =ROUND(5*1.5^A43,0)
...

Sheet Upgrade Matrix
A1: Effective upgrade values by tier x rarity (formulas)
A2: Rarity bonuses are editable inputs (green); everything below recalculates. Values feed from the Upgrades sheet.
A4: Rarity | B4: Bonus
A5: Common | B5: 0
A6: Uncommon | B6: 0.1
A7: Rare | B7: 0.25
A8: Epic | B8: 0.5
A11: Flat weapon damage bonus - Bullet Bounce (Primary & Secondary share values)
A12: Added to weapon baseDamagePerShot. Bounce count is not rarity-scaled: 1/2/3/4 by tier.
A13: Tier | B13: Common | C13: Uncommon | D13: Rare | E13: Epic
A14: Tier 1 | B14: =ROUND(Upgrades!$J$22*(1+$B$5),0) | C14: =ROUND(Upgrades!$J$22*(1+$B$6),0) | D14: =ROUND(Upgrades!$J$22*(1+$B$7),0) | E14: =ROUND(Upgrades!$J$22*(1+$B$8),0)
A15: Tier 2 | B15: =ROUND(Upgrades!$K$22*(1+$B$5),0) | C15: =ROUND(Upgrades!$K$22*(1+$B$6),0) | D15: =ROUND(Upgrades!$K$22*(1+$B$7),0) | E15: =ROUND(Upgrades!$K$22*(1+$B$8),0)
A16: Tier 3 | B16: =ROUND(Upgrades!$L$22*(1+$B$5),0) | C16: =ROUND(Upgrades!$L$22*(1+$B$6),0) | D16: =ROUND(Upgrades!$L$22*(1+$B$7),0) | E16: =ROUND(Upgrades!$L$22*(1+$B$8),0)
A17: Tier 4 | B17: =ROUND(Upgrades!$M$22*(1+$B$5),0) | C17: =ROUND(Upgrades!$M$22*(1+$B$6),0) | D17: =ROUND(Upgrades!$M$22*(1+$B$7),0) | E17: =ROUND(Upgrades!$M$22*(1+$B$8),0)
A19: Stomp damage bonus - Stomp Power (Mild)
A20: Tier | B20: Common | C20: Uncommon | D20: Rare | E20: Epic
A21: Tier 1 | B21: =ROUND(Upgrades!$J$17*(1+$B$5),0) | C21: =ROUND(Upgrades!$J$17*(1+$B$6),0) | D21: =ROUND(Upgrades!$J$17*(1+$B$7),0) | E21: =ROUND(Upgrades!$J$17*(1+$B$8),0)
A22: Tier 2 | B22: =ROUND(Upgrades!$K$17*(1+$B$5),0) | C22: =ROUND(Upgrades!$K$17*(1+$B$6),0) | D22: =ROUND(Upgrades!$K$17*(1+$B$7),0) | E22: =ROUND(Upgrades!$K$17*(1+$B$8),0)
A23: Tier 3 | B23: =ROUND(Upgrades!$L$17*(1+$B$5),0) | C23: =ROUND(Upgrades!$L$17*(1+$B$6),0) | D23: =ROUND(Upgrades!$L$17*(1+$B$7),0) | E23: =ROUND(Upgrades!$L$17*(1+$B$8),0)
A24: Tier 4 | B24: =ROUND(Upgrades!$M$17*(1+$B$5),0) | C24: =ROUND(Upgrades!$M$17*(1+$B$6),0) | D24: =ROUND(Upgrades!$M$17*(1+$B$7),0) | E24: =ROUND(Upgrades!$M$17*(1+$B$8),0)
A26: Stomp damage bonus - Stomp Circle (Regular; also = damage of EACH ring bullet)
A27: Ring bullet count by tier: 4/6/8/10 (not rarity-scaled).
A28: Tier | B28: Common | C28: Uncommon | D28: Rare | E28: Epic
A29: Tier 1 | B29: =ROUND(Upgrades!$J$26*(1+$B$5),0) | C29: =ROUND(Upgrades!$J$26*(1+$B$6),0) | D29: =ROUND(Upgrades!$J$26*(1+$B$7),0) | E29: =ROUND(Upgrades!$J$26*(1+$B$8),0)
A30: Tier 2 | B30: =ROUND(Upgrades!$K$26*(1+$B$5),0) | C30: =ROUND(Upgrades!$K$26*(1+$B$6),0) | D30: =ROUND(Upgrades!$K$26*(1+$B$7),0) | E30: =ROUND(Upgrades!$K$26*(1+$B$8),0)
A31: Tier 3 | B31: =ROUND(Upgrades!$L$26*(1+$B$5),0) | C31: =ROUND(Upgrades!$L$26*(1+$B$6),0) | D31: =ROUND(Upgrades!$L$26*(1+$B$7),0) | E31: =ROUND(Upgrades!$L$26*(1+$B$8),0)
A32: Tier 4 | B32: =ROUND(Upgrades!$M$26*(1+$B$5),0) | C32: =ROUND(Upgrades!$M$26*(1+$B$6),0) | D32: =ROUND(Upgrades!$M$26*(1+$B$7),0) | E32: =ROUND(Upgrades!$M$26*(1+$B$8),0)
A34: Dash AoE damage (once per enemy per dash)
A35: Tier | B35: Common | C35: Uncommon | D35: Rare | E35: Epic
A36: Tier 1 | B36: =ROUND(Upgrades!$J$19*(1+$B$5),0) | C36: =ROUND(Upgrades!$J$19*(1+$B$6),0) | D36: =ROUND(Upgrades!$J$19*(1+$B$7),0) | E36: =ROUND(Upgrades!$J$19*(1+$B$8),0)
A37: Tier 2 | B37: =ROUND(Upgrades!$K$19*(1+$B$5),0) | C37: =ROUND(Upgrades!$K$19*(1+$B$6),0) | D37: =ROUND(Upgrades!$K$19*(1+$B$7),0) | E37: =ROUND(Upgrades!$K$19*(1+$B$8),0)
A38: Tier 3 | B38: =ROUND(Upgrades!$L$19*(1+$B$5),0) | C38: =ROUND(Upgrades!$L$19*(1+$B$6),0) | D38: =ROUND(Upgrades!$L$19*(1+$B$7),0) | E38: =ROUND(Upgrades!$L$19*(1+$B$8),0)
A39: Tier 4 | B39: =ROUND(Upgrades!$M$19*(1+$B$5),0) | C39: =ROUND(Upgrades!$M$19*(1+$B$6),0) | D39: =ROUND(Upgrades!$M$19*(1+$B$7),0) | E39: =ROUND(Upgrades!$M$19*(1+$B$8),0)
A41: Dash AoE knockback impulse
A42: For scale: an ordinary hit applies Enemy.knockbackStrength = 25 in the current prefabs.
A43: Tier | B43: Common | C43: Uncommon | D43: Rare | E43: Epic
A44: Tier 1 | B44: =Upgrades!$J$20*(1+$B$5) | C44: =Upgrades!$J$20*(1+$B$6) | D44: =Upgrades!$J$20*(1+$B$7) | E44: =Upgrades!$J$20*(1+$B$8)
A45: Tier 2 | B45: =Upgrades!$K$20*(1+$B$5) | C45: =Upgrades!$K$20*(1+$B$6) | D45: =Upgrades!$K$20*(1+$B$7) | E45: =Upgrades!$K$20*(1+$B$8)
A46: Tier 3 | B46: =Upgrades!$L$20*(1+$B$5) | C46: =Upgrades!$L$20*(1+$B$6) | D46: =Upgrades!$L$20*(1+$B$7) | E46: =Upgrades!$L$20*(1+$B$8)
A47: Tier 4 | B47: =Upgrades!$M$20*(1+$B$5) | C47: =Upgrades!$M$20*(1+$B$6) | D47: =Upgrades!$M$20*(1+$B$7) | E47: =Upgrades!$M$20*(1+$B$8)
...

Sheet Enemies
A1: Enemies - comparison table
A2: Values are the serialized prefab values (what the game actually uses), not script defaults. Yellow = worth a look, see Findings sheet.
A4: Enemy | B4: Prefab | C4: Script | D4: In spawner roster? | E4: Max HP | F4: Move speed (u/s) | G4: Contact attackDamage field | H4: Effective dmg to player (coins/hit) | I4: Attack cooldown (s) | J4: Knockback strength | K4: Coins min | L4: Coins max | M4: Avg coins (formula) | N4: Spawner budget cost | O4: Spawner weight | P4: Spawner max allowed (lifetime) | Q4: Spawner group size | R4: Notes
A5: Enemy 1 | B5: Assets/Prefabs/Enemies/Enemy 1.prefab | C5: Enemy + EnemyMovement | D5: YES | E5: 50 | F5: 4 | G5: 25 | H5: =Player!$C$6 | I5: 1.5 | J5: 25 | K5: 4 | L5: 8 | M5: =(K5+L5)/2 | N5: 10 | O5: 2 | P5: 12 | Q5: 8 | R5: Melee lunger. attackDamage is NOT read by PlayerHealth (flat coins-per-hit instead).
A6: Enemy 2 | B6: Assets/Prefabs/Enemies/Enemy 2.prefab | C6: Enemy + EnemyMovement | D6: no (not referenced by spawner prefab) | E6: 100 | F6: 4 | G6: 25 | H6: =Player!$C$6 | I6: 1.5 | J6: 25 | K6: 1 | L6: 3 | M6: =(K6+L6)/2 | R6: Melee lunger. attackDamage is NOT read by PlayerHealth (flat coins-per-hit instead).
A7: Enemy 3 | B7: Assets/Prefabs/Enemies/Enemy 3.prefab | C7: Enemy + EnemyMovement | D7: no (not referenced by spawner prefab) | E7: 150 | F7: 4 | G7: 25 | H7: =Player!$C$6 | I7: 1.5 | J7: 25 | K7: 1 | L7: 3 | M7: =(K7+L7)/2 | R7: Melee lunger. attackDamage is NOT read by PlayerHealth (flat coins-per-hit instead).
A8: Enemy (base prefab) | B8: Assets/Prefabs/Enemies/Enemy.prefab | C8: Enemy + EnemyMovement | D8: no (base/template; 'Steve' instance inactive in scenes) | E8: 40 | F8: 3 | G8: 25 | H8: =Player!$C$6 | I8: 1.5 | J8: 25 | K8: 1 | L8: 3 | M8: =(K8+L8)/2 | R8: Older template. EnemyMovement here only has speed/drag fields (lunge fields exist only on Enemy 1-3).
A9: Ranged (Triangle/Squid) | B9: Assets/Prefabs/Enemies/RangedEnemy/RangedEnemy.prefab | C9: TriangleEnemy | D9: YES | E9: 150 | F9: 3 | G9: 10 | H9: =Player!$C$6 | I9: 1 | J9: n/a | K9: n/a (drops no coins) | L9: n/a | M9: 0 | N9: 50 | O9: 1 | P9: 2 | Q9: 1 | R9: Ranged: attackDamage column = bulletDamage. Fires 2 bullets/burst. Does not drop coins (no drop code). Registers kills.
A10: Cthulhu Eye | B10: Assets/Prefabs/Cthullu eye miniboss/CuthuluEye.prefab | C10: CthulhuEyeEnemy | D10: YES | E10: 300 | F10: 2 | G10: n/a (spawns pentagrams) | H10: see Pentagram table | I10: 5 | J10: n/a | K10: n/a (drops no coins) | L10: n/a | M10: 0 | N10: 100 | O10: 1 | P10: 1 | Q10: 1 | R10: Keeps preferredDistance from player; every attackCooldown drops a pentagram on the player. No coins, does NOT call EnemyKillTracker.
A11: Boss - MiniBoss1 | B11: Assets/Prefabs/Enemies/Boss_Prefab/MiniBoss1.prefab | C11: BossEnemy | D11: no (BossDefinition_01, BossArena) | E11: 4000 | F11: 6 | G11: 10 | H11: =Player!$C$6 | I11: 1.5 | J11: n/a | K11: 200 | L11: 250 | M11: =(K11+L11)/2 | R11: See Boss sheet. HP is behind a separate 1000-HP shield that regenerates each cycle.
A12: Boss1_Steve (legacy) | B12: Assets/Prefabs/Cthullu eye miniboss/Boss1_Steve.prefab | C12: BossEnemy | D12: no (legacy prefab) | E12: 500 | F12: 4 | G12: 10 | H12: =Player!$C$6 | I12: 1.5 | J12: n/a | K12: 10 | L12: 20 | M12: =(K12+L12)/2 | R12: Earlier boss prefab, not used by BossDefinition_01.
A14: Melee lunge / movement parameters (EnemyMovement)
A15: Enemy | B15: speed | C15: rotationSpeed | D15: attackTriggerDistance | E15: windupDistance | F15: lungeForce | G15: lungeDrag | H15: squashAmount | I15: separationRadius | J15: separationForce | K15: hitboxRadius (EnemyHitboxSetup) | L15: Source
A16: Enemy 1 | B16: 4 | C16: 5 | D16: 2 | E16: 0.2 | F16: 20 | G16: 5 | H16: 1.2 | I16: 1 | J16: 3 | K16: 0.76 | L16: Assets/Prefabs/Enemies/Enemy 1.prefab
A17: Enemy 2 | B17: 4 | C17: 5 | D17: 3 | E17: 0.5 | F17: 15 | G17: 5 | H17: 0.7 | I17: 0.4 | J17: 3 | K17: 0.47 | L17: Assets/Prefabs/Enemies/Enemy 2.prefab
A18: Enemy 3 | B18: 4 | C18: 5 | D18: 3 | E18: 0.5 | F18: 15 | G18: 5 | H18: 0.7 | I18: 1.5 | J18: 3 | K18: 0.47 | L18: Assets/Prefabs/Enemies/Enemy 3.prefab
A19: Enemy (base) | B19: 3 | L19: normalDrag=1, knockbackDrag=25 (base only)
A21: Ranged enemy details (TriangleEnemy)
A22: Parameter | B22: Value | C22: Unit | D22: Notes
A23: maxHealth | B23: 150 | C23: HP
A24: bulletDamage | B24: 10 | C24: field | D24: Ignored by PlayerHealth (flat coins per hit)
A25: bulletSpeed | B25: 4 | C25: u/s
A26: bulletLifetime | B26: 1 | C26: s | D26: -> range = speed*lifetime = 4 u
A27: fireRate | B27: 1 | C27: s between bursts | D27: 2 bullets per burst (bulletSpread apart)
A28: bulletSpread | B28: 10 | C28: deg
A29: minRange | B29: 2 | C29: u | D29: backs away inside this
A30: maxRange | B30: 4 | C30: u | D30: moves in beyond this
A31: moveSpeed | B31: 3 | C31: u/s
A32: roamTurnSpeed | B32: 90 | C32: deg/s
A33: wanderInterval | B33: 2 | C33: s
A34: wanderVariance | B34: 0.5 | C34: s
A35: attackTurnSpeed | B35: 320 | C35: deg/s
A36: aimTolerance | B36: 4 | C36: deg
A37: bullet range (derived) | B37: =B25*B26 | C37: u | D37: bulletSpeed * bulletLifetime (formula)
A39: Cthulhu Eye + pentagram attacks
A40: Parameter | B40: Value | C40: Unit | D40: Source / notes
A41: maxHealth | B41: 300 | C41: HP | D41: Assets/Prefabs/Cthullu eye miniboss/CuthuluEye.prefab
A42: moveSpeed | B42: 2 | C42: u/s | D42: Assets/Prefabs/Cthullu eye miniboss/CuthuluEye.prefab
A43: preferredDistance | B43: 5 | C43: u | D43: Assets/Prefabs/Cthullu eye miniboss/CuthuluEye.prefab
A44: distanceTolerance | B44: 1 | C44: u | D44: Assets/Prefabs/Cthullu eye miniboss/CuthuluEye.prefab
...

Sheet Spawner
A1: Enemy spawners
A2: Source: Assets/Prefabs/Enemies/Enemy Spawner.prefab + runtime code (DungeonMapGenerator.ConfigureSpawnerForRoom, EnemySpawner, RoguelikeManager).
A4: Parameter | B4: Value | C4: Unit | D4: Source | E4: Notes
A5: startingBudget | B5: 400 | C5: budget | D5: Assets/Prefabs/Enemies/Enemy Spawner.prefab | E5: Script default 300. Effective value is much higher after runtime modifiers (see below).
A6: spawnInterval | B6: 0.7 | C6: s | D6: Assets/Prefabs/Enemies/Enemy Spawner.prefab | E6: Overwritten at runtime by DungeonMapGenerator (random 1-3 s) before scaling.
A7: maxHealth (spawner is destructible) | B7: 300 | C7: HP | D7: Assets/Prefabs/Enemies/Enemy Spawner.prefab | E7: Killing it drops coins = round(remainingBudget * coinRewardMultiplier).
A8: coinRewardMultiplier | B8: 0.01 | C8: coins/budget | D8: Assets/Prefabs/Enemies/Enemy Spawner.prefab | E8: Script default 0.5; prefab 0.01.
A9: coinDropForce | B9: 2 | C9: impulse | D9: Assets/Prefabs/Enemies/Enemy Spawner.prefab
A10: cthulhuExclusionRadius | B10: 25 | C10: u | D10: Assets/Prefabs/Enemies/Enemy Spawner.prefab | E10: Only one Eye per 25 u across all spawners (global list).
A11: spawnRadius | B11: 5 | C11: u | D11: Assets/Prefabs/Enemies/Enemy Spawner.prefab | E11: Overwritten per room: clamp(max(roomW,roomH)/10*3, 2, 8).
A12: zoneOffset | B12: 1 | C12: u | D12: Assets/Prefabs/Enemies/Enemy Spawner.prefab | E12: Enemies spawn at 4 offsets (up/down/left/right) that are not inside walls.
A13: requiresActivation | B13: 1 | C13: bool | D13: Assets/Prefabs/Enemies/Enemy Spawner.prefab | E13: Starts when the player is within ActivateEnemySpawner.activationRange (7 u).
A14: maxEnemies | B14: 0 | C14: count | D14: Assets/Prefabs/Enemies/Enemy Spawner.prefab | E14: LEGACY. Set per room by the generator (8 + room bonus) but never read by EnemySpawner.
A16: Roster (enemy pool)
A17: Slot | B17: Enemy prefab | C17: budgetCost | D17: spawnWeight | E17: maxAllowed (0 = infinite) | F17: spawnGroupSize | G17: Notes
A18: fodderLevel1 | B18: ->Enemy 1 | C18: 10 | D18: 2 | E18: 12 | F18: 8 | G18: Only melee type actually spawned.
A19: fodderLevel2 | B19: (none) | C19: 0 | D19: 0 | E19: 0 | F19: 1 | G19: Empty slot (Enemy 2 prefab exists but is not wired in).
A20: fodderLevel3 | B20: (none) | C20: 0 | D20: 0 | E20: 0 | F20: 1 | G20: Empty slot (Enemy 3 prefab exists but is not wired in).
A21: rangedEnemy | B21: ->RangedEnemy | C21: 50 | D21: 1 | E21: 2 | F21: 1
A22: cthulhuEye | B22: ->CuthuluEye | C22: 100 | D22: 1 | E22: 1 | F22: 1 | G22: Also limited by the 25 u exclusion radius.
A24: Runtime modifiers (read from code - verify in play)
A25: Spawners per room | B25: random 1-3 (Random.Range(1,4)), capped by valid edge positions | D25: DungeonMapGenerator.SpawnEnemySpawnerInRoom | E25: Every room except start and end room.
A26: Min distance between spawners | B26: 5 | D26: DungeonMapGenerator.minDistanceBetweenSpawners (scene)
A27: Spawner respawn | B27: off (enableSpawnerRespawn=0) | D27: scene
A28: spawnInterval override | B28: Random.Range(1, 3) s per spawner | D28: ConfigureSpawnerForRoom | E28: Replaces prefab's 0.7 s.
A29: Level passed by the generator | B29: mapParametersSO.nodeCount (= 7 for Mapparametersso.asset), NOT the run level | D29: ConfigureSpawnerForRoom -> SetDungeonLevel | E29: So every spawner gets UpdateDifficultyForLevel(7): budget +350, interval -1.05 s (min 0.5).
A30: Second scaling pass | B30: RoguelikeManager.UpdateSpawnerDifficulty(currentLevel) | D30: RoguelikeManager | E30: For level > 1: budget += 50*level, interval = max(0.5, interval - 0.15*level). Level 1 skips.
A31: Budget is captured at Start() | B31: currentBudget = startingBudget at first frame, after both passes | D31: EnemySpawner.Start | E31: Generation is synchronous, so both passes happen before Start().
A32: Group spawn | B32: picks weighted enemy; spawns min(groupSize, affordable, maxAllowed-currentSpawned) at once | D32: EnemySpawner.AttemptSpawn
A33: currentSpawned never decrements | B33: maxAllowed is a LIFETIME cap per spawner, not a live cap | D33: EnemySpawner (no decrement found) | E33: Fodder 12 + Ranged 2 + Eye 1 = at most 15 enemies per spawner over its whole life.
A35: Projection by run level (formulas; assumes the two scaling passes above)
A36: Run level (currentLevel) | B36: Effective budget | C36: Interval, roll = 1 s | D36: Interval, roll = 2 s | E36: Interval, roll = 3 s | F36: Max enemies actually spawnable (lifetime cap) | G36: Budget spent at cap | H36: Budget left at cap (spawner stays alive)
A37: 1 | B37: =$B$5+350+IF(A37>1,50*A37,0) | C37: =MAX(0.5,MAX(0.5,1-1.05)-IF(A37>1,0.15*A37,0)) | D37: =MAX(0.5,MAX(0.5,2-1.05)-IF(A37>1,0.15*A37,0)) | E37: =MAX(0.5,MAX(0.5,3-1.05)-IF(A37>1,0.15*A37,0)) | F37: =MIN(E18,9999)+E21+E22 | G37: =E18*C18+E21*C21+E22*C22 | H37: =B37-G37
A38: 2 | B38: =$B$5+350+IF(A38>1,50*A38,0) | C38: =MAX(0.5,MAX(0.5,1-1.05)-IF(A38>1,0.15*A38,0)) | D38: =MAX(0.5,MAX(0.5,2-1.05)-IF(A38>1,0.15*A38,0)) | E38: =MAX(0.5,MAX(0.5,3-1.05)-IF(A38>1,0.15*A38,0)) | F38: =MIN(E18,9999)+E21+E22 | G38: =E18*C18+E21*C21+E22*C22 | H38: =B38-G38
A39: 3 | B39: =$B$5+350+IF(A39>1,50*A39,0) | C39: =MAX(0.5,MAX(0.5,1-1.05)-IF(A39>1,0.15*A39,0)) | D39: =MAX(0.5,MAX(0.5,2-1.05)-IF(A39>1,0.15*A39,0)) | E39: =MAX(0.5,MAX(0.5,3-1.05)-IF(A39>1,0.15*A39,0)) | F39: =MIN(E18,9999)+E21+E22 | G39: =E18*C18+E21*C21+E22*C22 | H39: =B39-G39
A40: 4 | B40: =$B$5+350+IF(A40>1,50*A40,0) | C40: =MAX(0.5,MAX(0.5,1-1.05)-IF(A40>1,0.15*A40,0)) | D40: =MAX(0.5,MAX(0.5,2-1.05)-IF(A40>1,0.15*A40,0)) | E40: =MAX(0.5,MAX(0.5,3-1.05)-IF(A40>1,0.15*A40,0)) | F40: =MIN(E18,9999)+E21+E22 | G40: =E18*C18+E21*C21+E22*C22 | H40: =B40-G40
A41: 5 | B41: =$B$5+350+IF(A41>1,50*A41,0) | C41: =MAX(0.5,MAX(0.5,1-1.05)-IF(A41>1,0.15*A41,0)) | D41: =MAX(0.5,MAX(0.5,2-1.05)-IF(A41>1,0.15*A41,0)) | E41: =MAX(0.5,MAX(0.5,3-1.05)-IF(A41>1,0.15*A41,0)) | F41: =MIN(E18,9999)+E21+E22 | G41: =E18*C18+E21*C21+E22*C22 | H41: =B41-G41
A42: 6 | B42: =$B$5+350+IF(A42>1,50*A42,0) | C42: =MAX(0.5,MAX(0.5,1-1.05)-IF(A42>1,0.15*A42,0)) | D42: =MAX(0.5,MAX(0.5,2-1.05)-IF(A42>1,0.15*A42,0)) | E42: =MAX(0.5,MAX(0.5,3-1.05)-IF(A42>1,0.15*A42,0)) | F42: =MIN(E18,9999)+E21+E22 | G42: =E18*C18+E21*C21+E22*C22 | H42: =B42-G42
A43: 7 | B43: =$B$5+350+IF(A43>1,50*A43,0) | C43: =MAX(0.5,MAX(0.5,1-1.05)-IF(A43>1,0.15*A43,0)) | D43: =MAX(0.5,MAX(0.5,2-1.05)-IF(A43>1,0.15*A43,0)) | E43: =MAX(0.5,MAX(0.5,3-1.05)-IF(A43>1,0.15*A43,0)) | F43: =MIN(E18,9999)+E21+E22 | G43: =E18*C18+E21*C21+E22*C22 | H43: =B43-G43
A44: Because the lifetime caps (15 enemies) cost less than the budget, the budget never runs out and 'budget <= 0 -> spawner dies' is never reached in practice.

Sheet Boss
A1: Boss - MiniBoss1 (BossDefinition_01)
A2: Source: Assets/Prefabs/Enemies/Boss_Prefab/MiniBoss1.prefab. BossArena scene spawns it via BossSceneManager.
A4: Parameter | B4: Value | C4: Unit | D4: Notes
A5: maxHealth | B5: 4000 | C5: HP | D5: Only damageable while the shield is down.
A6: shieldHealth | B6: 1000 | C6: HP | D6: Shield absorbs all damage first. Regenerates to full when the boss LEAVES a wall.
A7: Moves as pinball | B7: moveSpeed 6 -> +1 per wall bounce -> max 20 | C7: u/s | D7: While shielded it bounces off walls; once the shield breaks it sticks to the next wall it touches.
A8: moveSpeed | B8: 6 | C8: u/s
A9: maxSpeed | B9: 20 | C9: u/s
A10: speedIncreasePerBounce | B10: 1 | C10: u/s per bounce
A11: directionChangeInterval | B11: 20 | C11: s | D11: Field is not referenced in BossEnemy code (movement is bounce-driven).
A12: wallStickDuration | B12: 5 | C12: s | D12: Loop adds waves until this many seconds have elapsed.
A13: stickDistance | B13: 0.5 | C13: u
A14: timeBetweenWaves | B14: 0.3 | C14: s | D14: Delay between the two staggered rings of a cycle.
A15: timeBetweenAttacks | B15: 1 | C15: s | D15: Delay after the second ring.
A16: angleBetweenBullets | B16: 20 | C16: deg | D16: Ring size = ceil(360 / angle).
A17: bulletsPerWave (field) | B17: 12 | C17: count | D17: NOT USED by the code (ring size comes from angleBetweenBullets).
A18: bulletSpeed | B18: 8 | C18: u/s
A19: bulletLifetime | B19: 5 | C19: s
A20: bulletDamage | B20: 5 | C20: field | D20: Ignored by PlayerHealth (flat coin cost).
A21: attackDamage (contact) | B21: 10 | C21: field | D21: Ignored by PlayerHealth (flat coin cost).
A22: attackCooldown (contact) | B22: 1.5 | C22: s
A23: coins on death | B23: 200 - 250 | C23: coins | D23: Player purse is capped at startingMaxCoins (200).
A24: wallCheckDistance | B24: 1 | C24: u | D24: Ray length used to skip ring bullets that would spawn into a wall.
A26: Derived
A27: Bullets per ring (derived) | B27: =ROUNDUP(360/B16,0) | C27: bullets | D27: Wall-blocked directions are skipped, so fewer near walls.
A28: Loop time per cycle (derived) | B28: =B14+B15 | C28: s
A29: Cycles per wall stick (derived) | B29: =ROUNDUP(B12/(B14+B15),0) | C29: cycles | D29: While-loop runs until elapsed >= wallStickDuration.
A30: Rings per wall stick (derived) | B30: =2*B29 | C30: rings
A31: Bullets per wall stick (derived) | B31: =B30*B27 | C31: bullets | D31: Upper bound (walls block some).
A32: Damage the boss shield must absorb per cycle | B32: =B6 | C32: HP | D32: Shield resets after every wall stick; boss HP damage persists.
A33: Minimum shield-break cycles to kill (derived, if one stick = enough damage) | B33: depends on your DPS | D33: See TTK Matrix: shield 1000 + HP 4000 with your damage/shot. Vulnerable window = shield break -> wall stick end (<= ~5.2 s).

Sheet Run & Dungeon
A1: Run structure, dungeon generation, achievements & relics
A2: Scene values from RoguelikeMode.unity / BossArena.unity; presets from Assets/Scripts/Dungeon Generator/*.asset.
A4: Run flow (RoguelikeManager, scene values)
A5: Parameter | B5: Value | C5: Unit | D5: Source | E5: Notes
A6: roomsTillBoss | B6: 3 | C6: dungeons | D6: RoguelikeMode.unity > RoguelikeManager | E6: Scene = 3; the script default AND its comment say 5. The scene wins.
A7: Boss trigger | B7: after the Nth dungeon clear, skip the shop and go to BossArena | D7: RoguelikeManager.CompleteDungeon | E7: Shops therefore = roomsTillBoss - 1 (scene: 2).
A8: dungeonTimerEnabled | B8: 1 | C8: bool | D8: RoguelikeMode.unity > RoguelikeManager | E8: Scene = on (script default off).
A9: dungeonTimeLimit | B9: 120 | C9: s | D9: RoguelikeMode.unity > RoguelikeManager | E9: Timer expiring KILLS the player. Stops when the teleporter completes the dungeon (so it does not run in the shop) and restarts when the next dungeon generates.
A10: dungeonTimerWarningThreshold | B10: 15 | C10: s | D10: RoguelikeMode.unity > RoguelikeManager
A11: BASE_DUNGEON_SIZE (main-artery rooms) | B11: 5 | C11: rooms | D11: RoguelikeManager (hard-coded) | E11: Passed to GenerateNewMap(size) -> runtime nodeCount.
A12: SIZE_INCREASE_CHANCE | B12: 0.5 | C12: prob | D12: RoguelikeManager (hard-coded) | E12: After each shop, 50% chance size += 1 (persists).
A13: Run level increments | B13: +1 per ContinueDungeon() | D13: RoguelikeManager | E13: Feeds spawner scaling (see Spawner).
A14: Boss level | B14: BossArena via GameManager.AdvanceToBoss(); bossScene='BossArena' | D14: Boot.unity > GameManager | E14: Boss defeat = Demo Complete.
A15: Teleporter | B15: activationRadius 2, teleportDelay 1 s, requiresKey 0 | D15: Assets/Prefabs/Teleporter.prefab | E15: Key mechanic present but off (keyPrefab spawn disabled: shouldKeyBeSpawned=0).
A17: Dungeon generator presets (MapParametersSO) - RoguelikeMode & BossArena use 'Mapparametersso.asset'
A18: Parameter | B18: Mapparametersso.asset (IN USE) | C18: Mapparametersso Big.asset | D18: Mapparametersso 1.asset | E18: Notes
A19: nodeCount | B19: 7 | C19: 7 | D19: 7 | E19: Overridden at runtime by RoguelikeManager (5 + increments). Also the number passed to spawner difficulty (7).
A20: mainRoomSpacing | B20: 6 | C20: 6 | D20: 6
A21: chanceForLTurn | B21: 0.3 | C21: 0.3 | D21: 1
A22: mainArteryPositionJitter | B22: 2 | C22: 2 | D22: 2
A23: distributiveNodeChancePerSegment | B23: 0.858 | C23: 0.858 | D23: 0.858
A24: minLeafNodesPerDistributive | B24: 1 | C24: 1 | D24: 1
A25: maxLeafNodesPerDistributive | B25: 3 | C25: 3 | D25: 3
A26: leafBranchLength | B26: 6 | C26: 6 | D26: 6
A27: leafNodePositionJitter | B27: 1.5 | C27: 1.5 | D27: 1.5
A28: baseStartRoomSize | B28: (6, 6) | C28: (8, 8) | D28: (3, 3)
A29: baseEndRoomSize | B29: (8, 8) | C29: (10, 10) | D29: (8, 8)
A30: baseMainArteryRoomSize | B30: (7, 7) | C30: (8, 8) | D30: (7, 7)
A31: baseDistributiveRoomSize | B31: (5, 5) | C31: (8, 8) | D31: (5, 5)
A32: baseLeafRoomSize | B32: (5, 5) | C32: (7, 7) | D32: (5, 5)
A33: baseCornerRoomSize | B33: (4, 4) | C33: (6, 6) | D33: (4, 4)
A34: roomSizeVariationPercentage | B34: 0.331 | C34: 0.331 | D34: 0.812 | E34: +/- fraction applied to base room sizes
A35: minRoomDistance | B35: 0 | C35: 0 | D35: 1
A36: maxRepositionAttempts | B36: 30 | C36: 30 | D36: 30
A37: repositionSearchRadius | B37: 5 | C37: 5 | D37: 5
A38: startRoomToArteryDistance | B38: 12 | C38: 12 | D38: 12
A39: minStartToEndDistance | B39: 40 | C39: 40 | D39: 40
A40: roomRotationChance | B40: 0.5 | C40: 0.5 | D40: 1
A41: corridorWidth | B41: 4 | C41: 4 | D41: 6 | E41: tiles
A43: Dungeon generator scene settings (DungeonMapGenerator)
...

Sheet Economy
A1: Coin economy overview (sources, sinks, expectations)
A2: Coins are BOTH the currency and the player's health. Derived figures use formulas linked to the other sheets.
A4: Sources
A5: Source | B5: Avg coins per event | C5: Basis | D5: Notes
A6: Enemy 1 kill | B6: =Enemies!M5 | C6: Enemy 1 minCoins..maxCoins | D6: The only melee enemy spawned. Coin value = 1 each.
A7: Enemy 2 / Enemy 3 kill (if used) | B7: =Enemies!M6 | C7: min..max | D7: Not in the spawner roster.
A8: Ranged / Cthulhu Eye kill | B8: 0 | C8: no coin drop code | D8: Kills give no coins.
A9: Spawner destroyed | B9: =ROUND(Spawner!B5*0.01,0) | C9: remaining budget * 0.01 | D9: Uses base budget as a lower bound; effective budget is ~750+.
A10: Boss kill | B10: =Enemies!M11 | C10: 200-250 | D10: Above the 200-coin purse cap.
A11: Duplicate relic | B11: 0 (lifetime stat +50) | C11: RelicManager | D11: Does not credit the run purse.
A13: Sinks
A14: Sink | B14: Cost (coins) | C14: Basis | D14: Notes
A15: Taking a hit | B15: =Player!C6 | C15: coinsLostPerHit | D15: Also the player's HP loss.
A16: Upgrade purchase | B16: =Upgrades!H13 | C16: CigData.cost (all 10 except Electric-2 = 0)
A17: Reshuffle #1 | B17: 5 | C17: reshuffleBaseCost | D17: +50% compounding, see Upgrades sheet.
A18: Stomp (if enabled) | B18: 10 | C18: stompCoinCost | D18: Disabled (stompCostCoins = 0).
A20: Derived expectations (illustrative - edit inputs)
A21: Metric | B21: Value | C21: Formula basis | D21: Notes
A22: Fodder kills to afford one upgrade (10 coins) | B22: =ROUNDUP(10/B6,0) | C22: 10 / avg coins
A23: Fodder kills to refill 1 hit (30 coins) | B23: =ROUNDUP(Player!C6/B6,0) | C23: coinsLostPerHit / avg coins
A24: Kills to fill purse from 0 | B24: =ROUNDUP(Player!C15/B6,0) | C24: cap / avg coins
A25: Max fodder per spawner (lifetime cap) | B25: =Spawner!E18 | C25: maxAllowed | D25: At most this many Enemy 1 ever spawn from one spawner.
A26: Max coins from a spawner's fodder | B26: =B25*B6 | C26: cap * avg | D26: Upper bound per spawner, ignoring ranged/eye (no coins) and spawner-kill bonus.

Sheet Findings
A1: Findings & discrepancies spotted while collecting the data
A2: These are things that affect balancing decisions. Nothing here was changed in the project.
A4: # | B4: Area | C4: Finding | D4: Why it matters for balance | E4: Where
A5: 1 | B5: Damage model | C5: Every hit on the player costs a flat coinsLostPerHit (30). Enemy attackDamage, bulletDamage, boss bulletDamage and pentagram damage values are passed in but ignored. | D5: Tuning those numbers does nothing. To differentiate enemy damage, PlayerHealth.TakeDamage must use its damage argument. | E5: PlayerHealth.cs TakeDamage; Enemy.cs; Bullet.cs; BossEnemy.cs; EscapePentagram.cs
A6: 2 | B6: Health = coins | C6: Player HP is the coin balance (start 50, cap 200). At 30/hit that is 2 hits from start, ~7 hits from a full purse; spending coins in the shop lowers your HP. | D6: Shopping is a direct trade against survivability. | E6: PlayerHealth.cs; CoinManager (scene)
A7: 3 | B7: Scene vs script defaults | C7: roomsTillBoss: script 5 (comment says raised from 3) vs scene 3. dungeonTimerEnabled: script off vs scene ON with a 120 s limit that kills the player. coinsLostPerHit: script 100 vs prefab 30. | D7: Serialized values are what ships. Old notes and script defaults are misleading. | E7: RoguelikeManager.cs vs RoguelikeMode.unity
A8: 4 | B8: Spawner level scaling | C8: Generator always calls SetDungeonLevel(nodeCount=7) regardless of run level (+350 budget, -1.05 s interval), then RoguelikeManager adds +50*level budget and -0.15*level interval. Scaling is implemented, not deferred. | D8: In the shipping 3-dungeon run the effective budget is 750 / 850 / 900 (dungeon 1/2/3) and the interval sits at or near the 0.5 s floor, so difficulty barely changes between dungeons. | E8: DungeonMapGenerator.ConfigureSpawnerForRoom; EnemySpawner.UpdateDifficultyForLevel
A9: 5 | B9: Spawner lifetime cap | C9: SpawnableEnemy.currentSpawned is never decremented, so maxAllowed is a lifetime cap. One spawner produces at most 12 Enemy 1 + 2 Ranged + 1 Eye = 15 enemies, costing 320 of ~750+ budget. | D9: Budget is effectively irrelevant; enemy count per dungeon = spawners x 15 at most. Enemy 2/3 are not in the roster. | E9: EnemySpawner.cs; Enemy Spawner.prefab
A10: 6 | B10: Spawner interval override | C10: Prefab spawnInterval 0.7 is replaced by Random(1..3) at generation. | D10: Prefab value is not what plays. | E10: DungeonMapGenerator.cs:990
A11: 7 | B11: Relics do nothing | C11: The 8 relics have no gameplay effect; they only feed one achievement and duplicates add +50 to a lifetime stat. | D11: Nothing to balance yet; a duplicate 'coin reward' does not pay the run purse. | E11: RelicManager.cs
A12: 8 | B12: Shotgun damage model | C12: One shot deals pellet damage (150) to each distinct enemy hit, max one pellet per enemy. 6 pellets = up to 6 targets, not 900 to one. | D12: Bonus-pellet cig only helps against groups. Damage per target per shot = 150. | E12: PlayerConeShooter.FireShotgun
A13: 9 | B13: Weapon switch refill | C13: Switching weapons refills every magazine instantly. | D13: Free instant reload; AK/Shotgun swap-cancels reloads. | E13: WeaponAmmoManager.OnWeaponSwitched
A14: 10 | B14: Pistol unused | C14: Pistol.asset (Piercer, 100 dmg, 12 mag) is not in WeaponInventory.availableWeapons. Achievement reward text says it unlocks the Shotgun, which is already equipped. | D14: Only AK47 and Shotgun are balanced in practice. | E14: WeaponInventory / player prefab
A15: 11 | B15: Debug cigs in scene | C15: RoguelikeMode carries a DebugUpgradeInjector granting Chain Dash, Primary Dmg & Crit and Stomp Circle (Tier 1) at start. | D15: Playtest builds may start with 3 free upgrades. Confirm before measuring runs. | E15: RoguelikeMode.unity > __Pack Manager__
A16: 12 | B16: Cheat key in build | C16: Pressing I toggles invincibility even in non-development builds (enableToggleInBuild = 1). | D16: Balance/playtest data may be polluted; remove before release. | E16: PlayerHealth.cs
... A21: 17 | B21: GDD accuracy | C21: The earlier 1BitVed.md GDD was written from file names and the refactor plan without reading gameplay scripts. Its health, weapons (Pistol/Whip), relic effects, cooldowns and 'scaling unimplemented' claims are wrong or invented. | D21: Use THIS workbook as the source of numbers; 1BitVed.md needs a correction pass before any public use. | E21: 1BitVed.md

Sheet Raw Data
A1: Raw serialized values (balance-relevant components)
A2: Long format: one row per field. Colours, sprites, sorting, audio, gizmo/debug and visual-only components are excluded. Use the filter.
A4: File | B4: GameObject | C4: Component | D4: Field | E4: Value
A5: Assets/Prefabs/Coin.prefab | B5: Coin | C5: Coin | D5: coinValue | E5: 1
A6: Assets/Prefabs/Map_Generator.prefab | B6: Dungeon Spawner | C6: DungeonMapGenerator | D6: parameters | E6: {"numMainArteryRooms": 4, "mainRoomSpacing": 8, "chanceForLTurn": 0.5, "mainArteryPositionJitter": 2, "distributiveNodeChancePerSegment": 1, "minLeafNodesPerDistributive": 1, "maxLeafNodesPerDistributive": 2, "leafBranchLength": 6, "leafNodePositionJitter": 1.5, "baseStartRoomSize": {"x": 8, "y": 8}, "baseEndRoomSize": {"x": 8, "y": 8}, "baseMainArteryRoomSize": {"x": 8, "y": 6}, "baseDistributiveRoomSize": {"x": 4, "y": 4}, "baseLeafRoomSize": {"x": 12, "y": 4}, "baseCornerRoomSize": {"x": 3, "y": 3}, "roomSizeVariationPercentage": 0.465, "minRoomDistance": 4, "maxRepositionAttempts": 5, "repositionSearchRadius": 3, "corridorWidth": 2}
A7: Assets/Prefabs/Map_Generator.prefab | B7: Dungeon Spawner | C7: DungeonMapGenerator | D7: generateOnStart | E7: 1
A8: Assets/Prefabs/Map_Generator.prefab | B8: Dungeon Spawner | C8: DungeonMapGenerator | D8: showRoomIds | E8: 1
A9: Assets/Prefabs/Map_Generator.prefab | B9: Dungeon Spawner | C9: DungeonMapGenerator | D9: teleporterPrefab | E9: ->Teleporter
A10: Assets/Prefabs/Map_Generator.prefab | B10: Dungeon Spawner | C10: DungeonMapGenerator | D10: enemySpawnerPrefab | E10: ->Enemy Spawner
A11: Assets/Prefabs/Map_Generator.prefab | B11: Dungeon Spawner | C11: DungeonMapGenerator | D11: spawnEnemySpawnersInMainRooms | E11: 1
A12: Assets/Prefabs/Map_Generator.prefab | B12: Dungeon Spawner | C12: DungeonMapGenerator | D12: spawnerOffsetFromCenter | E12: 0
A13: Assets/Prefabs/Map_Generator.prefab | B13: Dungeon Spawner | C13: DungeonMapGenerator | D13: keyPrefab | E13: ->Key
A14: Assets/Prefabs/Map_Generator.prefab | B14: Dungeon Spawner | C14: DungeonMapGenerator | D14: hasKeyBeenSpawned | E14: 0
A15: Assets/Prefabs/Teleporter.prefab | B15: Teleporter | C15: Teleporter | D15: activationRadius | E15: 2
A16: Assets/Prefabs/Teleporter.prefab | B16: Teleporter | C16: Teleporter | D16: teleportDelay | E16: 1
A17: Assets/Prefabs/Teleporter.prefab | B17: Teleporter | C17: Teleporter | D17: glowIntensity | E17: 1
A18: Assets/Prefabs/Teleporter.prefab | B18: Teleporter | C18: Teleporter | D18: enemyTags | E18: Enemy, EnemySpawner, Coin, Relic
A19: Assets/Prefabs/Teleporter.prefab | B19: Teleporter | C19: Teleporter | D19: requiresKey | E19: 0
A20: Assets/Prefabs/Teleporter.prefab | B20: Teleporter | C20: Teleporter | D20: leadsToBossLevel | E20: 0
A21: Assets/Prefabs/Teleporter.prefab | B21: Teleporter | C21: Teleporter | D21: bossSceneName | E21: BossArena
A22: Assets/Prefabs/Temp -Player.prefab | B22: Temp -Player | C22: PlayerStompController | D22: stompRadius | E22: 2.5
A23: Assets/Prefabs/Temp -Player.prefab | B23: Temp -Player | C23: PlayerStompController | D23: stompDamage | E23: 50
A24: Assets/Prefabs/Temp -Player.prefab | B24: Temp -Player | C24: PlayerStompController | D24: stompPushBeyondRadius | E24: 0.5
A25: Assets/Prefabs/Temp -Player.prefab | B25: Temp -Player | C25: PlayerStompController | D25: stompCooldown | E25: 2
A26: Assets/Prefabs/Temp -Player.prefab | B26: Temp -Player | C26: PlayerStompController | D26: stompCostCoins | E26: 0
A27: Assets/Prefabs/Temp -Player.prefab | B27: Temp -Player | C27: PlayerStompController | D27: stompCoinCost | E27: 10
A28: Assets/Prefabs/Temp -Player.prefab | B28: Temp -Player | C28: PlayerStompController | D28: stompScreenShakeDuration | E28: 0.1
A29: Assets/Prefabs/Temp -Player.prefab | B29: Temp -Player | C29: PlayerStompController | D29: stompScreenShakeAmp | E29: 12
A30: Assets/Prefabs/Temp -Player.prefab | B30: Temp -Player | C30: PlayerStompController | D30: stompBulletSpeed | E30: 12
A31: Assets/Prefabs/Temp -Player.prefab | B31: Temp -Player | C31: PlayerStompController | D31: stompBulletLifetime | E31: 2
A32: Assets/Prefabs/Temp -Player.prefab | B32: Temp -Player | C32: PlayerController | D32: baseMoveSpeed | E32: 4
A33: Assets/Prefabs/Temp -Player.prefab | B33: Temp -Player | C33: PlayerController | D33: dashSpeed | E33: 20
... A58: Assets/Prefabs/Temp -Player.prefab | B58: Temp -Player | C58: PlayerKeyManagement | D58: hasKey | E58: 1
A59: Assets/Prefabs/Temp -Player.prefab | B59: Temp -Player | C59: PlayerKeyManagement | D59: keyTag | E59: Key
A60: Assets/Prefabs/Temp -Player.prefab | B60: Temp -Player | C60: PlayerKeyManagement | D60: teleporterTag | E60: Teleporter
A61: Assets/Prefabs/Temp -Player.prefab | B61: Temp -Player | C61: PlayerHealth | D61: coinsLostPerHit | E61: 30
A62: Assets/Prefabs/Temp -Player.prefab | B62: Temp -Player | C62: PlayerHealth | D62: useCoinsAsHealth | E62: 1
A63: Assets/Prefabs/Temp -Player.prefab | B63: Temp -Player | C63: PlayerHealth | D63: coinPrefab | E63: ->Coin
A64: Assets/Prefabs/Temp -Player.prefab | B64: Temp -Player | C64: PlayerHealth | D64: coinsToSpawnOnDamage | E64: 15
A65: Assets/Prefabs/Temp -Player.prefab | B65: Temp -Player | C65: PlayerHealth | D65: coinSpawnRadius | E65: 1
...
